Workbook

Sheet Sheet1
A1: Nr zlecenia | B1: Poz. | C1: Numer referencyjny | D1: KTC | E1: nowe / uĹĽywane | F1: Nazwa 1 | G1: Nazwa 2 | H1: dostarcz. IloĹ›Ä‡ | I1: Cena jednostkowa | J1: Cena Ĺ‚Ä…czna | K1: Pobranie | L1: Pracownicy | M1: Nr artykuĹ‚u | N1: Artikelnummer KROMI | O1: Centrum kosztĂłw | P1: Program | Q1: Konto ksiÄ™gowe | R1: Grund
A2: 2004657427 | B2: 1 | C2: 524067707 | D2: KTC-555 | E2: uĹĽywany | F2: Rozwiertak VHM | G2: C3 6,82-61-103 S10 Z2 | H2: 1 | I2: =_xlfn.XLOOKUP(G2, tablica!$R$3:$R$34, tablica!$T$3:$T$34) -> 165 | J2: =H2*I2 -> 165 | K2: 43107.449 | L2: 8888 | M2: =_xlfn.XLOOKUP(G2, tablica!$R$3:$R$34, tablica!$U$3:$U$34) -> 11000409 | N2: =_xlfn.XLOOKUP(G2, tablica!$R$3:$R$34, tablica!$V$3:$V$34) -> 490310551016 | O2: 1131980 | P2: Maszyna1 | Q2: DMG
A3: 2004657428 | B3: 1 | C3: 524067707 | D3: KTC-555 | E3: nowy | F3: Gwintownik HSS-E | G3: M8 TYP N R40 TIN IK | H3: 1 | I3: =_xlfn.XLOOKUP(G3, tablica!$R$3:$R$34, tablica!$T$3:$T$34) -> 259 | J3: =H3*I3 -> 259 | K3: 43107.45 | L3: 8888 | M3: =_xlfn.XLOOKUP(G3, tablica!$R$3:$R$34, tablica!$U$3:$U$34) -> 11000444 | N3: =_xlfn.XLOOKUP(G3, tablica!$R$3:$R$34, tablica!$V$3:$V$34) -> 244057088175 | O3: 1131980 | P3: Maszyna1 | Q3: DMG
A4: 2004657429 | B4: 1 | C4: 524067707 | D4: KTC-555 | E4: nowy | F4: PĹ‚ytka skrawajÄ…ca do wiercenia VHM | G4: 880-030305H-C-GR 1044 | H4: 10 | I4: =_xlfn.XLOOKUP(G4, tablica!$R$3:$R$34, tablica!$T$3:$T$34) -> 59 | J4: =H4*I4 -> 590 | K4: 43108.461 | L4: 8888 | M4: =_xlfn.XLOOKUP(G4, tablica!$R$3:$R$34, tablica!$U$3:$U$34) -> 11000490 | N4: =_xlfn.XLOOKUP(G4, tablica!$R$3:$R$34, tablica!$V$3:$V$34) -> 288866335589 | O4: 1131980 | P4: Maszyna1 | Q4: DMG
A5: 2004657430 | B5: 1 | C5: 524067707 | D5: KTC-555 | E5: nowy | F5: WiertĹ‚o stopniowe VHM | G5: C7 8,55x60x113 S12 Z2 | H5: 1 | I5: =_xlfn.XLOOKUP(G5, tablica!$R$3:$R$34, tablica!$T$3:$T$34) -> 169 | J5: =H5*I5 -> 169 | K5: 43109.367 | L5: 8888 | M5: =_xlfn.XLOOKUP(G5, tablica!$R$3:$R$34, tablica!$U$3:$U$34) -> 11000412 | N5: =_xlfn.XLOOKUP(G5, tablica!$R$3:$R$34, tablica!$V$3:$V$34) -> 176527023908 | O5: 1131980 | P5: Maszyna1 | Q5: DMG
A6: 2004657431 | B6: 1 | C6: 524067707 | D6: KTC-555 | E6: uĹĽywany | F6: Gwintownik HSS-E | G6: M10 | H6: 1 | I6: =_xlfn.XLOOKUP(G6, tablica!$R$3:$R$34, tablica!$T$3:$T$34) -> 50 | J6: =H6*I6 -> 50 | K6: 43109.367 | L6: 8888 | M6: =_xlfn.XLOOKUP(G6, tablica!$R$3:$R$34, tablica!$U$3:$U$34) -> 11000317 | N6: =_xlfn.XLOOKUP(G6, tablica!$R$3:$R$34, tablica!$V$3:$V$34) -> 241391757902 | O6: 1131980 | P6: Maszyna1 | Q6: DMG
A7: 2004657432 | B7: 1 | C7: 524067707 | D7: KTC-555 | E7: uĹĽywany | F7: WiertĹ‚o stopniowe VHM | G7: Dia. 13,5-83-133 S16 Z3 C7 | H7: 1 | I7: =_xlfn.XLOOKUP(G7, tablica!$R$3:$R$34, tablica!$T$3:$T$34) -> 145 | J7: =H7*I7 -> 145 | K7: 43110.292 | L7: 8888 | M7: =_xlfn.XLOOKUP(G7, tablica!$R$3:$R$34, tablica!$U$3:$U$34) -> 11000269 | N7: =_xlfn.XLOOKUP(G7, tablica!$R$3:$R$34, tablica!$V$3:$V$34) -> 363236906370 | O7: 1131980 | P7: Maszyna1 | Q7: DMG
A8: 2004657433 | B8: 1 | C8: 524067707 | D8: KTC-555 | E8: nowy | F8: PĹ‚ytka skrawajÄ…ca Ceramika | G8: SPHX1205PCTRGPBK KY3500 | H8: 5 | I8: =_xlfn.XLOOKUP(G8, tablica!$R$3:$R$34, tablica!$T$3:$T$34) -> 86 | J8: =H8*I8 -> 430 | K8: 43114.475 | L8: 8888 | M8: =_xlfn.XLOOKUP(G8, tablica!$R$3:$R$34, tablica!$U$3:$U$34) -> 11000265 | N8: =_xlfn.XLOOKUP(G8, tablica!$R$3:$R$34, tablica!$V$3:$V$34) -> 79046819988 | O8: 1131980 | P8: Maszyna1 | Q8: DMG
A9: 2004657434 | B9: 1 | C9: 524067707 | D9: KTC-555 | E9: uĹĽywany | F9: WiertĹ‚o stopniowe VHM | G9: Dia. 13,5-83-133 S16 Z3 C7 | H9: 1 | I9: =_xlfn.XLOOKUP(G9, tablica!$R$3:$R$34, tablica!$T$3:$T$34) -> 145 | J9: =H9*I9 -> 145 | K9: 43119.397 | L9: 8888 | M9: =_xlfn.XLOOKUP(G9, tablica!$R$3:$R$34, tablica!$U$3:$U$34) -> 11000269 | N9: =_xlfn.XLOOKUP(G9, tablica!$R$3:$R$34, tablica!$V$3:$V$34) -> 363236906370 | O9: 1131980 | P9: Maszyna1 | Q9: DMG
A10: 2004657435 | B10: 1 | C10: 524067707 | D10: KTC-555 | E10: nowy | F10: WiertĹ‚o stopniowe VHM | G10: C7 8,55x60x113 S12 Z2 | H10: 1 | I10: =_xlfn.XLOOKUP(G10, tablica!$R$3:$R$34, tablica!$T$3:$T$34) -> 169 | J10: =H10*I10 -> 169 | K10: 43124.449 | L10: 8888 | M10: =_xlfn.XLOOKUP(G10, tablica!$R$3:$R$34, tablica!$U$3:$U$34) -> 11000412 | N10: =_xlfn.XLOOKUP(G10, tablica!$R$3:$R$34, tablica!$V$3:$V$34) -> 176527023908 | O10: 1131980 | P10: Maszyna1 | Q10: DMG
A11: 2004657436 | B11: 1 | C11: 524067707 | D11: KTC-555 | E11: uĹĽywany | F11: Gwintownik HSS-E | G11: M10 | H11: 1 | I11: =_xlfn.XLOOKUP(G11, tablica!$R$3:$R$34, tablica!$T$3:$T$34) -> 50 | J11: =H11*I11 -> 50 | K11: 43124.45 | L11: 8888 | M11: =_xlfn.XLOOKUP(G11, tablica!$R$3:$R$34, tablica!$U$3:$U$34) -> 11000317 | N11: =_xlfn.XLOOKUP(G11, tablica!$R$3:$R$34, tablica!$V$3:$V$34) -> 241391757902 | O11: 1131980 | P11: Maszyna1 | Q11: DMG
A12: 2004657437 | B12: 1 | C12: 524067707 | D12: KTC-555 | E12: nowy | F12: PĹ‚ytka skrawajÄ…ca do toczenia VHM | G12: CNMG120412RP5 WKK20S | H12: 10 | I12: =_xlfn.XLOOKUP(G12, tablica!$R$3:$R$34, tablica!$T$3:$T$34) -> 217 | J12: =H12*I12 -> 2170 | K12: 43126.251 | L12: 8888 | M12: =_xlfn.XLOOKUP(G12, tablica!$R$3:$R$34, tablica!$U$3:$U$34) -> 11000428 | N12: =_xlfn.XLOOKUP(G12, tablica!$R$3:$R$34, tablica!$V$3:$V$34) -> 332966150556 | O12: 1131980 | P12: Maszyna1 | Q12: DMG
A13: 2004657438 | B13: 1 | C13: 524067707 | D13: KTC-555 | E13: uĹĽywany | F13: WiertĹ‚o stopniowe VHM | G13: Dia. 13,5-83-133 S16 Z3 C7 | H13: 1 | I13: =_xlfn.XLOOKUP(G13, tablica!$R$3:$R$34, tablica!$T$3:$T$34) -> 145 | J13: =H13*I13 -> 145 | K13: 43126.307 | L13: 8888 | M13: =_xlfn.XLOOKUP(G13, tablica!$R$3:$R$34, tablica!$U$3:$U$34) -> 11000269 | N13: =_xlfn.XLOOKUP(G13, tablica!$R$3:$R$34, tablica!$V$3:$V$34) -> 363236906370 | O13: 1131980 | P13: Maszyna1 | Q13: DMG
... A206: 2004657631 | B206: 1 | C206: 524072881 | D206: KTC-555 | E206: uĹĽywany | F206: Frez trzpieniowy VHM | G206: C3 Drm. 8,5-28,2-75 S10 Z3 | H206: 1 | I206: =_xlfn.XLOOKUP(G206, tablica!$R$3:$R$34, tablica!$T$3:$T$34) -> 271 | J206: =H206*I206 -> 271 | K206: 43431.644 | L206: 8888 | M206: =_xlfn.XLOOKUP(G206, tablica!$R$3:$R$34, tablica!$U$3:$U$34) -> 11000478 | N206: =_xlfn.XLOOKUP(G206, tablica!$R$3:$R$34, tablica!$V$3:$V$34) -> 438889327432 | O206: 1131980 | P206: Maszyna1 | Q206: DMG

Sheet tablica
A1: Nazwa 1 | B1: Nazwa 2 | C1: dostarcz. IloĹ›Ä‡ | D1: Cena jednostkowa | E1: Cena Ĺ‚Ä…czna | F1: Nr artykuĹ‚u | G1: Artikelnummer KROMI
A2: Rozwiertak VHM | B2: C3 6,82-61-103 S10 Z2 | C2: 1 | D2: 44.04 | E2: 44.04 | F2: 11004601 | G2: 501130090003-1
A3: Gwintownik HSS-E | B3: M8 TYP N R40 TIN IK | C3: 1 | D3: 28.47 | E3: 28.47 | F3: 11007545 | G3: 501150000000 | K3: C3 6,82-61-103 S10 Z2 | L3: =_xlfn.XLOOKUP(K3, $B$2:$B$206, $C$2:$C$206) -> 1 | M3: =_xlfn.XLOOKUP(K3, $B$2:$B$206, $D$2:$D$206) -> 44.04 | N3: =_xlfn.XLOOKUP(K3, $B$2:$B$206,$F$2:$F$206) -> 11004601 | O3: =_xlfn.XLOOKUP(K3, $B$2:$B$206,$G$2:$G$206) -> 501130090003-1 | R3: C3 6,82-61-103 S10 Z2 | S3: 1 | T3: 165 | U3: 11000409 | V3: 490310551016
A4: PĹ‚ytka skrawajÄ…ca do wiercenia VHM | B4: 880-030305H-C-GR 1044 | C4: 10 | D4: 10.44 | E4: 104.4 | F4: 943X9215 | G4: 501120000000 | K4: M8 TYP N R40 TIN IK | L4: =_xlfn.XLOOKUP(K4, $B$2:$B$206, $C$2:$C$206) -> 1 | M4: =_xlfn.XLOOKUP(K4, $B$2:$B$206, $D$2:$D$206) -> 28.47 | N4: =_xlfn.XLOOKUP(K4, $B$2:$B$206,$F$2:$F$206) -> 11007545 | O4: =_xlfn.XLOOKUP(K4, $B$2:$B$206,$G$2:$G$206) -> 501150000000 | R4: M8 TYP N R40 TIN IK | S4: 1 | T4: 259 | U4: 11000444 | V4: 244057088175
A5: WiertĹ‚o stopniowe VHM | B5: C7 8,55x60x113 S12 Z2 | C5: 1 | D5: 289.63 | E5: 289.63 | F5: 11004942 | G5: 501130000000 | K5: 880-030305H-C-GR 1044 | L5: =_xlfn.XLOOKUP(K5, $B$2:$B$206, $C$2:$C$206) -> 10 | M5: =_xlfn.XLOOKUP(K5, $B$2:$B$206, $D$2:$D$206) -> 10.44 | N5: =_xlfn.XLOOKUP(K5, $B$2:$B$206,$F$2:$F$206) -> 943X9215 | O5: =_xlfn.XLOOKUP(K5, $B$2:$B$206,$G$2:$G$206) -> 501120000000 | R5: 880-030305H-C-GR 1044 | S5: 10 | T5: 59 | U5: 11000490 | V5: 288866335589
A6: Gwintownik HSS-E | B6: M10 | C6: 1 | D6: 12.74 | E6: 12.74 | F6: 11091102 | G6: 501150100005-1 | K6: C7 8,55x60x113 S12 Z2 | L6: =_xlfn.XLOOKUP(K6, $B$2:$B$206, $C$2:$C$206) -> 1 | M6: =_xlfn.XLOOKUP(K6, $B$2:$B$206, $D$2:$D$206) -> 289.63 | N6: =_xlfn.XLOOKUP(K6, $B$2:$B$206,$F$2:$F$206) -> 11004942 | O6: =_xlfn.XLOOKUP(K6, $B$2:$B$206,$G$2:$G$206) -> 501130000000 | R6: C7 8,55x60x113 S12 Z2 | S6: 1 | T6: 169 | U6: 11000412 | V6: 176527023908
A7: WiertĹ‚o stopniowe VHM | B7: Dia. 13,5-83-133 S16 Z3 C7 | C7: 1 | D7: 67.91 | E7: 67.91 | F7: 943B3020 | G7: 501140240000-1 | K7: M10 | L7: =_xlfn.XLOOKUP(K7, $B$2:$B$206, $C$2:$C$206) -> 1 | M7: =_xlfn.XLOOKUP(K7, $B$2:$B$206, $D$2:$D$206) -> 12.74 | N7: =_xlfn.XLOOKUP(K7, $B$2:$B$206,$F$2:$F$206) -> 11091102 | O7: =_xlfn.XLOOKUP(K7, $B$2:$B$206,$G$2:$G$206) -> 501150100005-1 | R7: M10 | S7: 1 | T7: 50 | U7: 11000317 | V7: 241391757902
A8: PĹ‚ytka skrawajÄ…ca Ceramika | B8: SPHX1205PCTRGPBK KY3500 | C8: 5 | D8: 16.54 | E8: 82.7 | F8: 943X9988 | G8: 501121000000 | K8: Dia. 13,5-83-133 S16 Z3 C7 | L8: =_xlfn.XLOOKUP(K8, $B$2:$B$206, $C$2:$C$206) -> 1 | M8: =_xlfn.XLOOKUP(K8, $B$2:$B$206, $D$2:$D$206) -> 67.91 | N8: =_xlfn.XLOOKUP(K8, $B$2:$B$206,$F$2:$F$206) -> 943B3020 | O8: =_xlfn.XLOOKUP(K8, $B$2:$B$206,$G$2:$G$206) -> 501140240000-1 | R8: Dia. 13,5-83-133 S16 Z3 C7 | S8: 1 | T8: 145 | U8: 11000269 | V8: 363236906370
A9: WiertĹ‚o stopniowe VHM | B9: Dia. 13,5-83-133 S16 Z3 C7 | C9: 1 | D9: 67.91 | E9: 67.91 | F9: 943B3020 | G9: 501140240000-1 | K9: SPHX1205PCTRGPBK KY3500 | L9: =_xlfn.XLOOKUP(K9, $B$2:$B$206, $C$2:$C$206) -> 5 | M9: =_xlfn.XLOOKUP(K9, $B$2:$B$206, $D$2:$D$206) -> 16.54 | N9: =_xlfn.XLOOKUP(K9, $B$2:$B$206,$F$2:$F$206) -> 943X9988 | O9: =_xlfn.XLOOKUP(K9, $B$2:$B$206,$G$2:$G$206) -> 501121000000 | R9: SPHX1205PCTRGPBK KY3500 | S9: 5 | T9: 86 | U9: 11000265 | V9: 79046819988
A10: WiertĹ‚o stopniowe VHM | B10: C7 8,55x60x113 S12 Z2 | C10: 1 | D10: 289.63 | E10: 289.63 | F10: 11004942 | G10: 501130000000 | K10: CNMG120412RP5 WKK20S | L10: =_xlfn.XLOOKUP(K10, $B$2:$B$206, $C$2:$C$206) -> 10 | M10: =_xlfn.XLOOKUP(K10, $B$2:$B$206, $D$2:$D$206) -> 6.61 | N10: =_xlfn.XLOOKUP(K10, $B$2:$B$206,$F$2:$F$206) -> 501121000000 | O10: =_xlfn.XLOOKUP(K10, $B$2:$B$206,$G$2:$G$206) -> 501121000000 | R10: CNMG120412RP5 WKK20S | S10: 10 | T10: 217 | U10: 11000428 | V10: 332966150556
A11: Gwintownik HSS-E | B11: M10 | C11: 1 | D11: 12.74 | E11: 12.74 | F11: 11091102 | G11: 501150100005-1 | K11: WNMG080408WM3 TP1501 | L11: =_xlfn.XLOOKUP(K11, $B$2:$B$206, $C$2:$C$206) -> 10 | M11: =_xlfn.XLOOKUP(K11, $B$2:$B$206, $D$2:$D$206) -> 7.92 | N11: =_xlfn.XLOOKUP(K11, $B$2:$B$206,$F$2:$F$206) -> 943X1018 | O11: =_xlfn.XLOOKUP(K11, $B$2:$B$206,$G$2:$G$206) -> 501121000000 | R11: WNMG080408WM3 TP1501 | S11: 10 | T11: 156 | U11: 11000301 | V11: 440331456754
A12: PĹ‚ytka skrawajÄ…ca do toczenia VHM | B12: CNMG120412RP5 WKK20S | C12: 10 | D12: 6.61 | E12: 66.1 | F12: 501121000000 | G12: 501121000000 | K12: G1/2 GL=125mm IK TiAlN | L12: =_xlfn.XLOOKUP(K12, $B$2:$B$206, $C$2:$C$206) -> 1 | M12: =_xlfn.XLOOKUP(K12, $B$2:$B$206, $D$2:$D$206) -> 132.96 | N12: =_xlfn.XLOOKUP(K12, $B$2:$B$206,$F$2:$F$206) -> 943G0231 | O12: =_xlfn.XLOOKUP(K12, $B$2:$B$206,$G$2:$G$206) -> 501150000000 | R12: G1/2 GL=125mm IK TiAlN | S12: 1 | T12: 99 | U12: 11000495 | V12: 490068000560
A13: WiertĹ‚o stopniowe VHM | B13: Dia. 13,5-83-133 S16 Z3 C7 | C13: 1 | D13: 67.91 | E13: 67.91 | F13: 943B3020 | G13: 501140240000-1 | K13: Dia. 10,5x43x100 Z3 | L13: =_xlfn.XLOOKUP(K13, $B$2:$B$206, $C$2:$C$206) -> 1 | M13: =_xlfn.XLOOKUP(K13, $B$2:$B$206, $D$2:$D$206) -> 296.37 | N13: =_xlfn.XLOOKUP(K13, $B$2:$B$206,$F$2:$F$206) -> 11005753 | O13: =_xlfn.XLOOKUP(K13, $B$2:$B$206,$G$2:$G$206) -> 501140000000 | R13: Dia. 10,5x43x100 Z3 | S13: 1 | T13: 131 | U13: 11000241 | V13: 65225337712
A14: PĹ‚ytka skrawajÄ…ca do toczenia VHM | B14: WNMG080408WM3 TP1501 | C14: 10 | D14: 7.92 | E14: 79.2 | F14: 943X1018 | G14: 501121000000 | K14: Typ HPR Drm. 51,978 | L14: =_xlfn.XLOOKUP(K14, $B$2:$B$206, $C$2:$C$206) -> 1 | M14: =_xlfn.XLOOKUP(K14, $B$2:$B$206, $D$2:$D$206) -> 477.2 | N14: =_xlfn.XLOOKUP(K14, $B$2:$B$206,$F$2:$F$206) -> 943L1106 | O14: =_xlfn.XLOOKUP(K14, $B$2:$B$206,$G$2:$G$206) -> 501110519780-1 | R14: Typ HPR Drm. 51,978 | S14: 1 | T14: 81 | U14: 11000382 | V14: 253569993627
A15: WiertĹ‚o stopniowe VHM | B15: Dia. 13,5-83-133 S16 Z3 C7 | C15: 1 | D15: 67.91 | E15: 67.91 | F15: 943B3020 | G15: 501140240000-1 | K15: DCMX11T304WF 3210 | L15: =_xlfn.XLOOKUP(K15, $B$2:$B$206, $C$2:$C$206) -> 10 | M15: =_xlfn.XLOOKUP(K15, $B$2:$B$206, $D$2:$D$206) -> 8.13 | N15: =_xlfn.XLOOKUP(K15, $B$2:$B$206,$F$2:$F$206) -> 943X1085 | O15: =_xlfn.XLOOKUP(K15, $B$2:$B$206,$G$2:$G$206) -> 501120000000 | R15: DCMX11T304WF 3210 | S15: 10 | T15: 127 | U15: 11000307 | V15: 488714211366
A16: Gwintownik HSS-E | B16: G1/2 GL=125mm IK TiAlN | C16: 1 | D16: 132.96 | E16: 132.96 | F16: 943G0231 | G16: 501150000000 | K16: dia. 10,48X55x102,00mm Z= 3 | L16: =_xlfn.XLOOKUP(K16, $B$2:$B$206, $C$2:$C$206) -> 1 | M16: =_xlfn.XLOOKUP(K16, $B$2:$B$206, $D$2:$D$206) -> 193.97 | N16: =_xlfn.XLOOKUP(K16, $B$2:$B$206,$F$2:$F$206) -> 11007070 | O16: =_xlfn.XLOOKUP(K16, $B$2:$B$206,$G$2:$G$206) -> 501130000000 | R16: dia. 10,48X55x102,00mm Z= 3 | S16: 1 | T16: 51 | U16: 11000433 | V16: 101852761344
A17: PĹ‚ytka skrawajÄ…ca do toczenia VHM | B17: CNMG120412RP5 WKK20S | C17: 10 | D17: 6.61 | E17: 66.1 | F17: 501121000000 | G17: 501121000000 | K17: C3 Drm. 8,5-28,2-75 S10 Z3 | L17: =_xlfn.XLOOKUP(K17, $B$2:$B$206, $C$2:$C$206) -> 1 | M17: =_xlfn.XLOOKUP(K17, $B$2:$B$206, $D$2:$D$206) -> 27.44 | N17: =_xlfn.XLOOKUP(K17, $B$2:$B$206,$F$2:$F$206) -> 943U1786 | O17: =_xlfn.XLOOKUP(K17, $B$2:$B$206,$G$2:$G$206) -> 501160085000-1 | R17: C3 Drm. 8,5-28,2-75 S10 Z3 | S17: 1 | T17: 271 | U17: 11000478 | V17: 438889327432
A18: PĹ‚ytka skrawajÄ…ca Ceramika | B18: SPHX1205PCTRGPBK KY3500 | C18: 5 | D18: 16.54 | E18: 82.7 | F18: 943X9988 | G18: 501121000000 | K18: 7/8-14 UNF | L18: =_xlfn.XLOOKUP(K18, $B$2:$B$206, $C$2:$C$206) -> 1 | M18: =_xlfn.XLOOKUP(K18, $B$2:$B$206, $D$2:$D$206) -> 354.18 | N18: =_xlfn.XLOOKUP(K18, $B$2:$B$206,$F$2:$F$206) -> 943G0229 | O18: =_xlfn.XLOOKUP(K18, $B$2:$B$206,$G$2:$G$206) -> 501150000000 | R18: 7/8-14 UNF | S18: 1 | T18: 107 | U18: 11000217 | V18: 369830830390
A19: WiertĹ‚o stopniowe VHM | B19: Dia. 13,5-83-133 S16 Z3 C7 | C19: 1 | D19: 67.91 | E19: 67.91 | F19: 943B3020 | G19: 501140240000-1 | K19: C3 7,55-20-75 Z4 | L19: =_xlfn.XLOOKUP(K19, $B$2:$B$206, $C$2:$C$206) -> 1 | M19: =_xlfn.XLOOKUP(K19, $B$2:$B$206, $D$2:$D$206) -> 0.01 | N19: =_xlfn.XLOOKUP(K19, $B$2:$B$206,$F$2:$F$206) -> 11004613 | O19: =_xlfn.XLOOKUP(K19, $B$2:$B$206,$G$2:$G$206) -> 501140000000 | R19: C3 7,55-20-75 Z4 | S19: 1 | T19: 151 | U19: 11000217 | V19: 248226542077
A20: WiertĹ‚o stopniowe VHM | B20: Dia. 13,5-83-133 S16 Z3 C7 | C20: 1 | D20: 318.69 | E20: 318.69 | F20: 943B3020 | G20: 501140000000 | K20: DNMX110404-WF 3225 | L20: =_xlfn.XLOOKUP(K20, $B$2:$B$206, $C$2:$C$206) -> 10 | M20: =_xlfn.XLOOKUP(K20, $B$2:$B$206, $D$2:$D$206) -> 8.8 | N20: =_xlfn.XLOOKUP(K20, $B$2:$B$206,$F$2:$F$206) -> 11130302 | O20: =_xlfn.XLOOKUP(K20, $B$2:$B$206,$G$2:$G$206) -> 501121000000 | R20: DNMX110404-WF 3225 | S20: 10 | T20: 220 | U20: 11000256 | V20: 385416301012
A21: WiertĹ‚o stopniowe VHM | B21: Dia. 10,5x43x100 Z3 | C21: 1 | D21: 296.37 | E21: 296.37 | F21: 11005753 | G21: 501140000000 | K21: CNMG120412-NM5 WAK20 | L21: =_xlfn.XLOOKUP(K21, $B$2:$B$206, $C$2:$C$206) -> 10 | M21: =_xlfn.XLOOKUP(K21, $B$2:$B$206, $D$2:$D$206) -> 6.61 | N21: =_xlfn.XLOOKUP(K21, $B$2:$B$206,$F$2:$F$206) -> 11147007 | O21: =_xlfn.XLOOKUP(K21, $B$2:$B$206,$G$2:$G$206) -> 501121000000 | R21: CNMG120412-NM5 WAK20 | S21: 10 | T21: 208 | U21: 11000364 | V21: 437465821622
A22: Rozwiertak jednostopniowy HM | B22: Typ HPR Drm. 51,978 | C22: 1 | D22: 477.2 | E22: 477.2 | F22: 943L1106 | G22: 501110519780-1 | K22: Drm. 12,7mm Typ RT 100 U FIRE | L22: =_xlfn.XLOOKUP(K22, $B$2:$B$206, $C$2:$C$206) -> 1 | M22: =_xlfn.XLOOKUP(K22, $B$2:$B$206, $D$2:$D$206) -> 0.01 | N22: =_xlfn.XLOOKUP(K22, $B$2:$B$206,$F$2:$F$206) -> 943B2908 | O22: =_xlfn.XLOOKUP(K22, $B$2:$B$206,$G$2:$G$206) -> 501130127000-2 | R22: Drm. 12,7mm Typ RT 100 U FIRE | S22: 1 | T22: 180 | U22: 11000309 | V22: 288924799473
A23: Gwintownik HSS-E | B23: M10 | C23: 1 | D23: 12.74 | E23: 12.74 | F23: 11091102 | G23: 501150100005-1 | K23: RCKT10T3M0PM 4220 | L23: =_xlfn.XLOOKUP(K23, $B$2:$B$206, $C$2:$C$206) -> 10 | M23: =_xlfn.XLOOKUP(K23, $B$2:$B$206, $D$2:$D$206) -> 0.01 | N23: =_xlfn.XLOOKUP(K23, $B$2:$B$206,$F$2:$F$206) -> 943X1105 | O23: =_xlfn.XLOOKUP(K23, $B$2:$B$206,$G$2:$G$206) -> 501120103000-2 | R23: RCKT10T3M0PM 4220 | S23: 10 | T23: 87 | U23: 11000442 | V23: 356319291959
A24: PĹ‚ytka skrawajÄ…ca do toczenia VHM | B24: DCMX11T304WF 3210 | C24: 10 | D24: 8.13 | E24: 81.3 | F24: 943X1085 | G24: 501120000000 | K24: VHM Drm. 25,0 mm | L24: =_xlfn.XLOOKUP(K24, $B$2:$B$206, $C$2:$C$206) -> 1 | M24: =_xlfn.XLOOKUP(K24, $B$2:$B$206, $D$2:$D$206) -> 0.01 | N24: =_xlfn.XLOOKUP(K24, $B$2:$B$206,$F$2:$F$206) -> 501130000000 | O24: =_xlfn.XLOOKUP(K24, $B$2:$B$206,$G$2:$G$206) -> 501130250000-2 | R24: VHM Drm. 25,0 mm | S24: 1 | T24: 149 | U24: 11000335 | V24: 55095376362
A25: PĹ‚ytka skrawajÄ…ca do toczenia VHM | B25: CNMG120412RP5 WKK20S | C25: 10 | D25: 6.61 | E25: 66.1 | F25: 501121000000 | G25: 501121000000 | K25: 880-03 03 W06H-P-GR 4344 | L25: =_xlfn.XLOOKUP(K25, $B$2:$B$206, $C$2:$C$206) -> 10 | M25: =_xlfn.XLOOKUP(K25, $B$2:$B$206, $D$2:$D$206) -> 10.44 | N25: =_xlfn.XLOOKUP(K25, $B$2:$B$206,$F$2:$F$206) -> 943X9992 | O25: =_xlfn.XLOOKUP(K25, $B$2:$B$206,$G$2:$G$206) -> 501120000000 | R25: 880-03 03 W06H-P-GR 4344 | S25: 10 | T25: 78 | U25: 11000351 | V25: 134264669804
A26: PĹ‚ytka skrawajÄ…ca do toczenia VHM | B26: WNMG080408WM3 TP1501 | C26: 10 | D26: 7.92 | E26: 79.2 | F26: 943X1018 | G26: 501121000000 | K26: dia 6,6x10h6x26x100 Z2 | L26: =_xlfn.XLOOKUP(K26, $B$2:$B$206, $C$2:$C$206) -> 1 | M26: =_xlfn.XLOOKUP(K26, $B$2:$B$206, $D$2:$D$206) -> 116.14 | N26: =_xlfn.XLOOKUP(K26, $B$2:$B$206,$F$2:$F$206) -> 11005357 | O26: =_xlfn.XLOOKUP(K26, $B$2:$B$206,$G$2:$G$206) -> 501130000000 | R26: dia 6,6x10h6x26x100 Z2 | S26: 1 | T26: 44 | U26: 11000452 | V26: 202953108877
A27: WiertĹ‚o stopniowe VHM | B27: C7 8,55x60x113 S12 Z2 | C27: 1 | D27: 289.63 | E27: 289.63 | F27: 11004942 | G27: 501130000000 | K27: P4840P-3R-A57 WKP35 | L27: =_xlfn.XLOOKUP(K27, $B$2:$B$206, $C$2:$C$206) -> 10 | M27: =_xlfn.XLOOKUP(K27, $B$2:$B$206, $D$2:$D$206) -> 9.99 | N27: =_xlfn.XLOOKUP(K27, $B$2:$B$206,$F$2:$F$206) -> 11100679 | O27: =_xlfn.XLOOKUP(K27, $B$2:$B$206,$G$2:$G$206) -> 501120000000 | R27: P4840P-3R-A57 WKP35 | S27: 10 | T27: 158 | U27: 11000171 | V27: 137061556926
A28: Gwintownik HSS-E | B28: M10 | C28: 1 | D28: 12.74 | E28: 12.74 | F28: 11091102 | G28: 501150100005-1 | K28: P4841C-3R-E57 WXP40 | L28: =_xlfn.XLOOKUP(K28, $B$2:$B$206, $C$2:$C$206) -> 10 | M28: =_xlfn.XLOOKUP(K28, $B$2:$B$206, $D$2:$D$206) -> 8.27 | N28: =_xlfn.XLOOKUP(K28, $B$2:$B$206,$F$2:$F$206) -> 11100680 | O28: =_xlfn.XLOOKUP(K28, $B$2:$B$206,$G$2:$G$206) -> 501120000000 | R28: P4841C-3R-E57 WXP40 | S28: 10 | T28: 78 | U28: 11000137 | V28: 66309439958
A29: Rozwiertak VHM | B29: dia. 10,48X55x102,00mm Z= 3 | C29: 1 | D29: 193.97 | E29: 193.97 | F29: 11007070 | G29: 501130000000 | K29: Dia. 4,0 mm | L29: =_xlfn.XLOOKUP(K29, $B$2:$B$206, $C$2:$C$206) -> 1 | M29: =_xlfn.XLOOKUP(K29, $B$2:$B$206, $D$2:$D$206) -> 0.01 | N29: =_xlfn.XLOOKUP(K29, $B$2:$B$206,$F$2:$F$206) -> 11004594 | O29: =_xlfn.XLOOKUP(K29, $B$2:$B$206,$G$2:$G$206) -> 501160000000 | R29: Dia. 4,0 mm | S29: 1 | T29: 281 | U29: 11000481 | V29: 408378663366
A30: Frez trzpieniowy VHM | B30: C3 Drm. 8,5-28,2-75 S10 Z3 | C30: 1 | D30: 27.44 | E30: 27.44 | F30: 943U1786 | G30: 501160085000-1 | K30: VHM BOHRER KU 2.6mm/.1024/ 3xD IK / B976Z02600 KCU15 | L30: =_xlfn.XLOOKUP(K30, $B$2:$B$206, $C$2:$C$206) -> 1 | M30: =_xlfn.XLOOKUP(K30, $B$2:$B$206, $D$2:$D$206) -> 39.36 | N30: =_xlfn.XLOOKUP(K30, $B$2:$B$206,$F$2:$F$206) -> WM384-KE0 | O30: =_xlfn.XLOOKUP(K30, $B$2:$B$206,$G$2:$G$206) -> 501130000000 | R30: VHM BOHRER KU 2.6mm/.1024/ 3xD IK / B976Z02600 KCU15 | S30: 1 | T30: 188 | U30: 11000374 | V30: 64578011490
A31: WiertĹ‚o stopniowe VHM | B31: Dia. 10,5x43x100 Z3 | C31: 1 | D31: 296.37 | E31: 296.37 | F31: 11005753 | G31: 501140000000 | K31: Step Drill Ă10,5Ă22Ă22h6x110; Z2 | L31: =_xlfn.XLOOKUP(K31, $B$2:$B$206, $C$2:$C$206) -> 1 | M31: =_xlfn.XLOOKUP(K31, $B$2:$B$206, $D$2:$D$206) -> 371.57 | N31: =_xlfn.XLOOKUP(K31, $B$2:$B$206,$F$2:$F$206) -> WM383-WE1 | O31: =_xlfn.XLOOKUP(K31, $B$2:$B$206,$G$2:$G$206) -> 501140000000 | R31: Step Drill Ă10,5Ă22Ă22h6x110; Z2 | S31: 1 | T31: 269 | U31: 11000407 | V31: 375370388922
A32: Gwintownik HSS-E | B32: 7/8-14 UNF | C32: 1 | D32: 354.18 | E32: 354.18 | F32: 943G0229 | G32: 501150000000 | K32: VPO-DC-MT MF12x1,5 DIN374 | L32: =_xlfn.XLOOKUP(K32, $B$2:$B$206, $C$2:$C$206) -> 1 | M32: =_xlfn.XLOOKUP(K32, $B$2:$B$206, $D$2:$D$206) -> 0.01 | N32: =_xlfn.XLOOKUP(K32, $B$2:$B$206,$F$2:$F$206) -> GW59-OS0 | O32: =_xlfn.XLOOKUP(K32, $B$2:$B$206,$G$2:$G$206) -> 501150000000 | R32: VPO-DC-MT MF12x1,5 DIN374 | S32: 1 | T32: 41 | U32: 11000469 | V32: 398696407933
A33: PĹ‚ytka skrawajÄ…ca Ceramika | B33: SPHX1205PCTRGPBK KY3500 | C33: 5 | D33: 16.54 | E33: 82.7 | F33: 943X9988 | G33: 501121000000 | K33: 3CH2000DK020A KC633M | L33: =_xlfn.XLOOKUP(K33, $B$2:$B$206, $C$2:$C$206) -> 1 | M33: =_xlfn.XLOOKUP(K33, $B$2:$B$206, $D$2:$D$206) -> 96.47 | N33: =_xlfn.XLOOKUP(K33, $B$2:$B$206,$F$2:$F$206) -> FP55-KE0 | O33: =_xlfn.XLOOKUP(K33, $B$2:$B$206,$G$2:$G$206) -> 501160000000 | R33: 3CH2000DK020A KC633M | S33: 1 | T33: 56 | U33: 11000234 | V33: 443385592730
A34: WiertĹ‚o stopniowe VHM | B34: C3 7,55-20-75 Z4 | C34: 1 | D34: 0.01 | E34: 0.01 | F34: 11004613 | G34: 501140000000 | K34: M8x1,25mm 6HX | L34: =_xlfn.XLOOKUP(K34, $B$2:$B$206, $C$2:$C$206) -> 1 | M34: =_xlfn.XLOOKUP(K34, $B$2:$B$206, $D$2:$D$206) -> 23.35 | N34: =_xlfn.XLOOKUP(K34, $B$2:$B$206,$F$2:$F$206) -> 943G0175 | O34: =_xlfn.XLOOKUP(K34, $B$2:$B$206,$G$2:$G$206) -> 501150000000 | R34: M8x1,25mm 6HX | S34: 1 | T34: 180 | U34: 11000322 | V34: 279589783878
A35: Rozwiertak VHM | B35: C3 6,82-61-103 S10 Z2 | C35: 1 | D35: 318.65 | E35: 318.65 | F35: 11004601 | G35: 501130000000
A36: Gwintownik HSS-E | B36: M8 TYP N R40 TIN IK | C36: 1 | D36: 28.47 | E36: 28.47 | F36: 11007545 | G36: 501150000000
A37: PĹ‚ytka skrawajÄ…ca do toczenia VHM | B37: DNMX110404-WF 3225 | C37: 10 | D37: 8.8 | E37: 88 | F37: 11130302 | G37: 501121000000
A38: PĹ‚ytka skrawajÄ…ca do toczenia VHM | B38: WNMG080408WM3 TP1501 | C38: 10 | D38: 7.92 | E38: 79.2 | F38: 943X1018 | G38: 501121000000
A39: PĹ‚ytka skrawajÄ…ca do toczenia VHM | B39: WNMG080408WM3 TP1501 | C39: 10 | D39: 7.92 | E39: 79.2 | F39: 943X1018 | G39: 501121000000
A40: PĹ‚ytka skrawajÄ…ca do toczenia VHM | B40: CNMG120412-NM5 WAK20 | C40: 10 | D40: 6.61 | E40: 66.1 | F40: 11147007 | G40: 501121000000
...
